Failure # 1 (occurred at 2023-02-01_17-27-26)
[36mray::ImplicitFunc.train()[39m (pid=6896, ip=127.0.0.1, repr=func)
  File "python\ray\_raylet.pyx", line 830, in ray._raylet.execute_task
  File "python\ray\_raylet.pyx", line 834, in ray._raylet.execute_task
  File "python\ray\_raylet.pyx", line 780, in ray._raylet.execute_task.function_executor
  File "C:\Users\matte\AppData\Local\Programs\Python\Python39\lib\site-packages\ray\_private\function_manager.py", line 674, in actor_method_executor
    return method(__ray_actor, *args, **kwargs)
  File "C:\Users\matte\AppData\Local\Programs\Python\Python39\lib\site-packages\ray\util\tracing\tracing_helper.py", line 466, in _resume_span
    return method(self, *_args, **_kwargs)
  File "C:\Users\matte\AppData\Local\Programs\Python\Python39\lib\site-packages\ray\tune\trainable\trainable.py", line 367, in train
    raise skipped from exception_cause(skipped)
  File "C:\Users\matte\AppData\Local\Programs\Python\Python39\lib\site-packages\ray\tune\trainable\function_trainable.py", line 335, in entrypoint
    return self._trainable_func(
  File "C:\Users\matte\AppData\Local\Programs\Python\Python39\lib\site-packages\ray\util\tracing\tracing_helper.py", line 466, in _resume_span
    return method(self, *_args, **_kwargs)
  File "C:\Users\matte\AppData\Local\Programs\Python\Python39\lib\site-packages\ray\tune\trainable\function_trainable.py", line 652, in _trainable_func
    output = fn()
  File "C:\Users\matte\Desktop\deep-seasonal-color-analysis-system\models\training_and_testing.py", line 109, in train_model
    average_train_loss, average_train_score = training_or_testing_epoch_(
  File "C:\Users\matte\Desktop\deep-seasonal-color-analysis-system\models\training_and_testing.py", line 31, in training_or_testing_epoch_
    batch_outputs = model(batch_inputs)[0]
  File "C:\Users\matte\AppData\Local\Programs\Python\Python39\lib\site-packages\torch\nn\modules\module.py", line 1194, in _call_impl
    return forward_call(*input, **kwargs)
  File "C:\Users\matte\Desktop\deep-seasonal-color-analysis-system\models\local\CGNet\model\CGNet.py", line 342, in forward
    output1_0 = self.level2_0(output0_cat) # down-sampled
  File "C:\Users\matte\AppData\Local\Programs\Python\Python39\lib\site-packages\torch\nn\modules\module.py", line 1194, in _call_impl
    return forward_call(*input, **kwargs)
  File "C:\Users\matte\Desktop\deep-seasonal-color-analysis-system\models\local\CGNet\model\CGNet.py", line 221, in forward
    joi_feat = self.bn(joi_feat)
  File "C:\Users\matte\AppData\Local\Programs\Python\Python39\lib\site-packages\torch\nn\modules\module.py", line 1194, in _call_impl
    return forward_call(*input, **kwargs)
  File "C:\Users\matte\AppData\Local\Programs\Python\Python39\lib\site-packages\torch\nn\modules\batchnorm.py", line 171, in forward
    return F.batch_norm(
  File "C:\Users\matte\AppData\Local\Programs\Python\Python39\lib\site-packages\torch\nn\functional.py", line 2450, in batch_norm
    return torch.batch_norm(
torch.cuda.OutOfMemoryError: CUDA out of memory. Tried to allocate 64.00 MiB (GPU 0; 2.00 GiB total capacity; 1.11 GiB already allocated; 0 bytes free; 1.15 GiB reserved in total by PyTorch) If reserved memory is >> allocated memory try setting max_split_size_mb to avoid fragmentation.  See documentation for Memory Management and PYTORCH_CUDA_ALLOC_CONF
